Workbook

Sheet 2020年权重图表
A1: 根据南华商品指数编制细则的规定，南华期货有限公司将于2020年6月1日调整南华商品指数权重，调整后的权重如下：
A2: 品种名称 | B2: 南华商品指数 | C2: 南华工业品指数 | D2: 南华金属指数 | E2: 南华能化指数 | F2: 南华农产品指数 | G2: 南华贵金属指数 | H2: 南华黑色指数 | I2: 南华有色金属指数
A3: 原油 | B3: 0.1786 | C3: 0.1894 | E3: 0.25
A4: 螺纹钢 | B4: 0.1093 | C4: 0.1266 | D4: 0.25 | H4: 0.3755
A5: 铁矿石 | B5: 0.0885 | C5: 0.1016 | D5: 0.2293 | H5: 0.3009
A6: 铜 | B6: 0.0809 | C6: 0.0928 | D6: 0.2095 | I6: 0.3894
A7: 镍 | B7: 0.05 | C7: 0.061 | D7: 0.1258 | I7: 0.2342
A8: 天然橡胶 | B8: 0.0442 | C8: 0.0541 | E8: 0.1084
A9: 焦炭 | B9: 0.0673 | C9: 0.0737 | E9: 0.1223 | H9: 0.2162
A10: 黄金 | B10: 0.0451
A11: 豆粕 | B11: 0.0401 | F11: 0.1596 | G11: 0.5935
A12: 锌 | B12: 0.0371 | C12: 0.0443 | D12: 0.0941 | I12: 0.1752
A13: 苹果 | B13: 0.0422 | F13: 0.1639
A14: 白糖 | B14: 0.0279 | F14: 0.1125
A15: PTA | B15: 0.0325 | C15: 0.0377 | E15: 0.0693
A16: 白银 | B16: 0.026 | G16: 0.4065
A17: 棕榈油 | B17: 0.0223 | F17: 0.0911
A18: 豆油 | B18: 0.0234 | F18: 0.0934
A19: 甲醇 | B19: 0.024 | C19: 0.028 | E19: 0.0521
A20: 燃料油 | B20: 0.02 | C20: 0.0226 | E20: 0.043
A21: 一号棉 | B21: 0.0206 | F21: 0.0814
A22: 乙二醇 | B22: 0.02 | C22: 0.0215 | E22: 0.0462
A23: 聚丙烯 | C23: 0.0258 | E23: 0.0479
A24: 聚乙烯 | C24: 0.028 | E24: 0.0406
A25: 铝 | C25: 0.0357 | D25: 0.0913 | I25: 0.1693
A26: 石油沥青 | C26: 0.02 | E26: 0.0555
A27: 菜籽油 | F27: 0.0483
A28: 焦煤 | C28: 0.0372 | E28: 0.1133 | H28: 0.1074
A29: 动力煤 | E29: 0.0283
A30: 纸浆 | E30: 0.0231
A31: 玉米 | F31: 0.0948
A32: 鸡蛋 | F32: 0.0538
A33: 玻璃
A34: 黄大豆一号 | F34: 0.0812
A35: PVC
A36: 玉米淀粉 | F36: 0.02
A37: 铅 | I37: 0.0319
A38: 锰硅
A39: 锡
A40: 硅铁
...

Sheet Sheet1
A1: 根据南华商品指数编制细则的规定，南华期货有限公司将于2020年6月1日调整南华商品指数权重，调整后的权重如下：
A2: 品种名称 | B2: 南华商品指数 | C2: 南华工业品指数 | D2: 南华金属指数 | E2: 南华能化指数 | F2: 南华农产品指数 | G2: 南华贵金属指数 | H2: 南华黑色指数 | I2: 南华有色金属指数
A3: 原油 | B3: 0.1786 | C3: 0.1894 | E3: 0.25
A4: 螺纹钢 | B4: 0.1093 | C4: 0.1266 | D4: 0.25 | H4: 0.3755
A5: 铁矿石 | B5: 0.0885 | C5: 0.1016 | D5: 0.2293 | H5: 0.3009
A6: 铜 | B6: 0.0809 | C6: 0.0928 | D6: 0.2095 | I6: 0.3894
A7: 焦炭 | B7: 0.0673 | C7: 0.0737 | E7: 0.1223 | H7: 0.2162
A8: 镍 | B8: 0.05 | C8: 0.061 | D8: 0.1258 | I8: 0.2342
A9: 黄金 | B9: 0.0451
A10: 天然橡胶 | B10: 0.0442 | C10: 0.0541 | E10: 0.1084
A11: 苹果 | B11: 0.0422 | F11: 0.1639
A12: 豆粕 | B12: 0.0401 | F12: 0.1596 | G12: 0.6509
A13: 锌 | B13: 0.0371 | C13: 0.0443 | D13: 0.0941 | I13: 0.1752
A14: PTA | B14: 0.0325 | C14: 0.0377 | E14: 0.0693
A15: 白糖 | B15: 0.0279 | F15: 0.1125
A16: 白银 | B16: 0.026 | G16: 0.3491
A17: 甲醇 | B17: 0.024 | C17: 0.028 | E17: 0.0521
A18: 豆油 | B18: 0.0234 | F18: 0.0934
A19: 棕榈油 | B19: 0.0223 | F19: 0.0911
A20: 燃料油 | B20: 0.02 | C20: 0.0226 | E20: 0.043
A21: 一号棉 | B21: 0.0206 | F21: 0.0814
A22: 乙二醇 | B22: 0.02 | C22: 0.0215 | E22: 0.0462
A23: 聚丙烯 | C23: 0.0258 | E23: 0.0479
A24: 聚乙烯 | C24: 0.028 | E24: 0.0406
A25: 铝 | C25: 0.0357 | D25: 0.0913 | I25: 0.1693
A26: 石油沥青 | C26: 0.02 | E26: 0.0555
A27: 菜籽油 | F27: 0.0483
A28: 焦煤 | C28: 0.0372 | E28: 0.1133 | H28: 0.1074
A29: 动力煤 | E29: 0.0283
A30: 纸浆 | E30: 0.0231
A31: 玉米 | F31: 0.0948
A32: 鸡蛋 | F32: 0.0538
A33: 玻璃
A34: 黄大豆一号 | F34: 0.0812
A35: PVC
A36: 玉米淀粉 | F36: 0.02
A37: 铅 | I37: 0.0319
A38: 锰硅
A39: 锡
A40: 硅铁
...

Sheet Sheet2
A1: 根据南华商品指数编制细则的规定，南华期货有限公司将于2019年6月1日调整南华商品指数权重，具体调整如下：
A2: 品种名称 | B2: 南华商品指数 | C2: 南华工业品指数 | D2: 南华金属指数 | E2: 南华能化指数 | F2: 南华农产品指数 | G2: 南华贵金属指数 | H2: 南华黑色指数 | I2: 南华有色金属指数
A3: 原油 | B3: 0.1786 | C3: =VLOOKUP($A3,Sheet3!C$2:D$10,2,FALSE) -> 0.1894 | D3: =VLOOKUP($A3,Sheet3!G$2:H$6,2,FALSE) -> #N/A | E3: =VLOOKUP($A3,Sheet3!I$2:J$5,2,FALSE) -> 0.25 | F3: =VLOOKUP($A3,Sheet3!E$2:F$6,2,FALSE) -> #N/A | G3: =VLOOKUP($A3,Sheet3!K$2:L$17,2,FALSE) -> #N/A | H3: =VLOOKUP($A3,Sheet3!M$2:N$17,2,FALSE) -> #N/A | I3: =VLOOKUP($A3,Sheet3!O$2:P$17,2,FALSE) -> #N/A
A4: 螺纹钢 | B4: 0.1093 | C4: =VLOOKUP($A4,Sheet3!C$2:D$10,2,FALSE) -> 0.1266 | D4: =VLOOKUP($A4,Sheet3!G$2:H$6,2,FALSE) -> 0.25 | E4: =VLOOKUP($A4,Sheet3!I$2:J$5,2,FALSE) -> #N/A | F4: =VLOOKUP($A4,Sheet3!E$2:F$6,2,FALSE) -> #N/A | G4: =VLOOKUP($A4,Sheet3!K$2:L$17,2,FALSE) -> #N/A | H4: =VLOOKUP($A4,Sheet3!M$2:N$17,2,FALSE) -> 0.3755 | I4: =VLOOKUP($A4,Sheet3!O$2:P$17,2,FALSE) -> #N/A
A5: 铁矿石 | B5: 0.0885 | C5: =VLOOKUP($A5,Sheet3!C$2:D$10,2,FALSE) -> 0.1016 | D5: =VLOOKUP($A5,Sheet3!G$2:H$6,2,FALSE) -> 0.2293 | E5: =VLOOKUP($A5,Sheet3!I$2:J$5,2,FALSE) -> #N/A | F5: =VLOOKUP($A5,Sheet3!E$2:F$6,2,FALSE) -> #N/A | G5: =VLOOKUP($A5,Sheet3!K$2:L$17,2,FALSE) -> #N/A | H5: =VLOOKUP($A5,Sheet3!M$2:N$17,2,FALSE) -> 0.3009 | I5: =VLOOKUP($A5,Sheet3!O$2:P$17,2,FALSE) -> #N/A
A6: 铜 | B6: 0.0809 | C6: =VLOOKUP($A6,Sheet3!C$2:D$10,2,FALSE) -> 0.0928 | D6: =VLOOKUP($A6,Sheet3!G$2:H$6,2,FALSE) -> 0.2095 | E6: =VLOOKUP($A6,Sheet3!I$2:J$5,2,FALSE) -> #N/A | F6: =VLOOKUP($A6,Sheet3!E$2:F$6,2,FALSE) -> #N/A | G6: =VLOOKUP($A6,Sheet3!K$2:L$17,2,FALSE) -> #N/A | H6: =VLOOKUP($A6,Sheet3!M$2:N$17,2,FALSE) -> #N/A | I6: =VLOOKUP($A6,Sheet3!O$2:P$17,2,FALSE) -> 0.3894
A7: 镍 | B7: 0.05 | C7: =VLOOKUP($A7,Sheet3!C$2:D$10,2,FALSE) -> 0.061 | D7: =VLOOKUP($A7,Sheet3!G$2:H$6,2,FALSE) -> 0.1258 | E7: =VLOOKUP($A7,Sheet3!I$2:J$5,2,FALSE) -> #N/A | F7: =VLOOKUP($A7,Sheet3!E$2:F$6,2,FALSE) -> #N/A | G7: =VLOOKUP($A7,Sheet3!K$2:L$17,2,FALSE) -> #N/A | H7: =VLOOKUP($A7,Sheet3!M$2:N$17,2,FALSE) -> #N/A | I7: =VLOOKUP($A7,Sheet3!O$2:P$17,2,FALSE) -> 0.2342
A8: 天然橡胶 | B8: 0.0442 | C8: =VLOOKUP($A8,Sheet3!C$2:D$10,2,FALSE) -> 0.0541 | D8: =VLOOKUP($A8,Sheet3!G$2:H$6,2,FALSE) -> #N/A | E8: =VLOOKUP($A8,Sheet3!I$2:J$5,2,FALSE) -> 0.1084 | F8: =VLOOKUP($A8,Sheet3!E$2:F$6,2,FALSE) -> #N/A | G8: =VLOOKUP($A8,Sheet3!K$2:L$17,2,FALSE) -> #N/A | H8: =VLOOKUP($A8,Sheet3!M$2:N$17,2,FALSE) -> #N/A | I8: =VLOOKUP($A8,Sheet3!O$2:P$17,2,FALSE) -> #N/A
A9: 焦炭 | B9: 0.0673 | C9: =VLOOKUP($A9,Sheet3!C$2:D$10,2,FALSE) -> 0.0737 | D9: =VLOOKUP($A9,Sheet3!G$2:H$6,2,FALSE) -> #N/A | E9: =VLOOKUP($A9,Sheet3!I$2:J$5,2,FALSE) -> 0.1223 | F9: =VLOOKUP($A9,Sheet3!E$2:F$6,2,FALSE) -> #N/A | G9: =VLOOKUP($A9,Sheet3!K$2:L$17,2,FALSE) -> #N/A | H9: =VLOOKUP($A9,Sheet3!M$2:N$17,2,FALSE) -> 0.2162 | I9: =VLOOKUP($A9,Sheet3!O$2:P$17,2,FALSE) -> #N/A
A10: 黄金 | B10: 0.0451 | C10: =VLOOKUP($A10,Sheet3!C$2:D$10,2,FALSE) -> #N/A | D10: =VLOOKUP($A10,Sheet3!G$2:H$6,2,FALSE) -> #N/A | E10: =VLOOKUP($A10,Sheet3!I$2:J$5,2,FALSE) -> #N/A | F10: =VLOOKUP($A10,Sheet3!E$2:F$6,2,FALSE) -> #N/A | G10: =VLOOKUP($A10,Sheet3!K$2:L$17,2,FALSE) -> 0.5935 | H10: =VLOOKUP($A10,Sheet3!M$2:N$17,2,FALSE) -> #N/A | I10: =VLOOKUP($A10,Sheet3!O$2:P$17,2,FALSE) -> #N/A
A11: 豆粕 | B11: 0.0401 | C11: =VLOOKUP($A11,Sheet3!C$2:D$10,2,FALSE) -> #N/A | D11: =VLOOKUP($A11,Sheet3!G$2:H$6,2,FALSE) -> #N/A | E11: =VLOOKUP($A11,Sheet3!I$2:J$5,2,FALSE) -> #N/A | F11: =VLOOKUP($A11,Sheet3!E$2:F$6,2,FALSE) -> 0.1596 | G11: =VLOOKUP($A11,Sheet3!K$2:L$17,2,FALSE) -> #N/A | H11: =VLOOKUP($A11,Sheet3!M$2:N$17,2,FALSE) -> #N/A | I11: =VLOOKUP($A11,Sheet3!O$2:P$17,2,FALSE) -> #N/A
A12: 锌 | B12: 0.0371 | C12: =VLOOKUP($A12,Sheet3!C$2:D$10,2,FALSE) -> 0.0443 | D12: =VLOOKUP($A12,Sheet3!G$2:H$6,2,FALSE) -> 0.0941 | E12: =VLOOKUP($A12,Sheet3!I$2:J$5,2,FALSE) -> #N/A | F12: =VLOOKUP($A12,Sheet3!E$2:F$6,2,FALSE) -> #N/A | G12: =VLOOKUP($A12,Sheet3!K$2:L$17,2,FALSE) -> #N/A | H12: =VLOOKUP($A12,Sheet3!M$2:N$17,2,FALSE) -> #N/A | I12: =VLOOKUP($A12,Sheet3!O$2:P$17,2,FALSE) -> 0.1752
A13: 苹果 | B13: 0.0422 | C13: =VLOOKUP($A13,Sheet3!C$2:D$10,2,FALSE) -> #N/A | D13: =VLOOKUP($A13,Sheet3!G$2:H$6,2,FALSE) -> #N/A | E13: =VLOOKUP($A13,Sheet3!I$2:J$5,2,FALSE) -> #N/A | F13: =VLOOKUP($A13,Sheet3!E$2:F$6,2,FALSE) -> 0.1639 | G13: =VLOOKUP($A13,Sheet3!K$2:L$17,2,FALSE) -> #N/A | H13: =VLOOKUP($A13,Sheet3!M$2:N$17,2,FALSE) -> #N/A | I13: =VLOOKUP($A13,Sheet3!O$2:P$17,2,FALSE) -> #N/A
A14: 白糖 | B14: 0.0279 | C14: =VLOOKUP($A14,Sheet3!C$2:D$10,2,FALSE) -> #N/A | D14: =VLOOKUP($A14,Sheet3!G$2:H$6,2,FALSE) -> #N/A | E14: =VLOOKUP($A14,Sheet3!I$2:J$5,2,FALSE) -> #N/A | F14: =VLOOKUP($A14,Sheet3!E$2:F$6,2,FALSE) -> 0.1125 | G14: =VLOOKUP($A14,Sheet3!K$2:L$17,2,FALSE) -> #N/A | H14: =VLOOKUP($A14,Sheet3!M$2:N$17,2,FALSE) -> #N/A | I14: =VLOOKUP($A14,Sheet3!O$2:P$17,2,FALSE) -> #N/A
... A22: 乙二醇 | B22: 0.02 | C22: =VLOOKUP($A22,Sheet3!C$2:D$10,2,FALSE) -> #N/A | D22: =VLOOKUP($A22,Sheet3!G$2:H$6,2,FALSE) -> #N/A | E22: =VLOOKUP($A22,Sheet3!I$2:J$5,2,FALSE) -> #N/A | F22: =VLOOKUP($A22,Sheet3!E$2:F$6,2,FALSE) -> #N/A | G22: =VLOOKUP($A22,Sheet3!K$2:L$17,2,FALSE) -> #N/A | H22: =VLOOKUP($A22,Sheet3!M$2:N$17,2,FALSE) -> #N/A | I22: =VLOOKUP($A22,Sheet3!O$2:P$17,2,FALSE) -> #N/A
A23: 聚丙烯 | C23: =VLOOKUP($A23,Sheet3!C$2:D$10,2,FALSE) -> #N/A | D23: =VLOOKUP($A23,Sheet3!G$2:H$6,2,FALSE) -> #N/A | E23: =VLOOKUP($A23,Sheet3!I$2:J$5,2,FALSE) -> #N/A | F23: =VLOOKUP($A23,Sheet3!E$2:F$6,2,FALSE) -> #N/A | G23: =VLOOKUP($A23,Sheet3!K$2:L$17,2,FALSE) -> #N/A | H23: =VLOOKUP($A23,Sheet3!M$2:N$17,2,FALSE) -> #N/A | I23: =VLOOKUP($A23,Sheet3!O$2:P$17,2,FALSE) -> #N/A
A24: 聚乙烯 | C24: =VLOOKUP($A24,Sheet3!C$2:D$10,2,FALSE) -> #N/A | D24: =VLOOKUP($A24,Sheet3!G$2:H$6,2,FALSE) -> #N/A | E24: =VLOOKUP($A24,Sheet3!I$2:J$5,2,FALSE) -> #N/A | F24: =VLOOKUP($A24,Sheet3!E$2:F$6,2,FALSE) -> #N/A | G24: =VLOOKUP($A24,Sheet3!K$2:L$17,2,FALSE) -> #N/A | H24: =VLOOKUP($A24,Sheet3!M$2:N$17,2,FALSE) -> #N/A | I24: =VLOOKUP($A24,Sheet3!O$2:P$17,2,FALSE) -> #N/A
A25: 铝 | C25: =VLOOKUP($A25,Sheet3!C$2:D$10,2,FALSE) -> #N/A | D25: =VLOOKUP($A25,Sheet3!G$2:H$6,2,FALSE) -> #N/A | E25: =VLOOKUP($A25,Sheet3!I$2:J$5,2,FALSE) -> #N/A | F25: =VLOOKUP($A25,Sheet3!E$2:F$6,2,FALSE) -> #N/A | G25: =VLOOKUP($A25,Sheet3!K$2:L$17,2,FALSE) -> #N/A | H25: =VLOOKUP($A25,Sheet3!M$2:N$17,2,FALSE) -> #N/A | I25: =VLOOKUP($A25,Sheet3!O$2:P$17,2,FALSE) -> 0.1693
A26: 石油沥青 | C26: =VLOOKUP($A26,Sheet3!C$2:D$10,2,FALSE) -> #N/A | D26: =VLOOKUP($A26,Sheet3!G$2:H$6,2,FALSE) -> #N/A | E26: =VLOOKUP($A26,Sheet3!I$2:J$5,2,FALSE) -> #N/A | F26: =VLOOKUP($A26,Sheet3!E$2:F$6,2,FALSE) -> #N/A | G26: =VLOOKUP($A26,Sheet3!K$2:L$17,2,FALSE) -> #N/A | H26: =VLOOKUP($A26,Sheet3!M$2:N$17,2,FALSE) -> #N/A | I26: =VLOOKUP($A26,Sheet3!O$2:P$17,2,FALSE) -> #N/A
A27: 菜籽油 | C27: =VLOOKUP($A27,Sheet3!C$2:D$10,2,FALSE) -> #N/A | D27: =VLOOKUP($A27,Sheet3!G$2:H$6,2,FALSE) -> #N/A | E27: =VLOOKUP($A27,Sheet3!I$2:J$5,2,FALSE) -> #N/A | F27: =VLOOKUP($A27,Sheet3!E$2:F$6,2,FALSE) -> #N/A | H27: =VLOOKUP($A27,Sheet3!M$2:N$17,2,FALSE) -> #N/A | I27: =VLOOKUP($A27,Sheet3!O$2:P$17,2,FALSE) -> #N/A
A28: 焦煤 | C28: =VLOOKUP($A28,Sheet3!C$2:D$10,2,FALSE) -> #N/A | D28: =VLOOKUP($A28,Sheet3!G$2:H$6,2,FALSE) -> #N/A | E28: =VLOOKUP($A28,Sheet3!I$2:J$5,2,FALSE) -> 0.1133 | F28: =VLOOKUP($A28,Sheet3!E$2:F$6,2,FALSE) -> #N/A | H28: =VLOOKUP($A28,Sheet3!M$2:N$17,2,FALSE) -> 0.1074 | I28: =VLOOKUP($A28,Sheet3!O$2:P$17,2,FALSE) -> #N/A
A29: 动力煤 | C29: =VLOOKUP($A29,Sheet3!C$2:D$10,2,FALSE) -> #N/A | D29: =VLOOKUP($A29,Sheet3!G$2:H$6,2,FALSE) -> #N/A | E29: =VLOOKUP($A29,Sheet3!I$2:J$5,2,FALSE) -> #N/A | F29: =VLOOKUP($A29,Sheet3!E$2:F$6,2,FALSE) -> #N/A | H29: =VLOOKUP($A29,Sheet3!M$2:N$17,2,FALSE) -> #N/A | I29: =VLOOKUP($A29,Sheet3!O$2:P$17,2,FALSE) -> #N/A
A30: 纸浆 | C30: =VLOOKUP($A30,Sheet3!C$2:D$10,2,FALSE) -> #N/A | D30: =VLOOKUP($A30,Sheet3!G$2:H$6,2,FALSE) -> #N/A | E30: =VLOOKUP($A30,Sheet3!I$2:J$5,2,FALSE) -> #N/A | F30: =VLOOKUP($A30,Sheet3!E$2:F$6,2,FALSE) -> #N/A | H30: =VLOOKUP($A30,Sheet3!M$2:N$17,2,FALSE) -> #N/A | I30: =VLOOKUP($A30,Sheet3!O$2:P$17,2,FALSE) -> #N/A
A31: 玉米 | C31: =VLOOKUP($A31,Sheet3!C$2:D$10,2,FALSE) -> #N/A | D31: =VLOOKUP($A31,Sheet3!G$2:H$6,2,FALSE) -> #N/A | E31: =VLOOKUP($A31,Sheet3!I$2:J$5,2,FALSE) -> #N/A | F31: =VLOOKUP($A31,Sheet3!E$2:F$6,2,FALSE) -> 0.0948 | H31: =VLOOKUP($A31,Sheet3!M$2:N$17,2,FALSE) -> #N/A
A32: 鸡蛋 | C32: =VLOOKUP($A32,Sheet3!C$2:D$10,2,FALSE) -> #N/A | D32: =VLOOKUP($A32,Sheet3!G$2:H$6,2,FALSE) -> #N/A | E32: =VLOOKUP($A32,Sheet3!I$2:J$5,2,FALSE) -> #N/A | F32: =VLOOKUP($A32,Sheet3!E$2:F$6,2,FALSE) -> #N/A | H32: =VLOOKUP($A32,Sheet3!M$2:N$17,2,FALSE) -> #N/A
A33: 玻璃 | C33: =VLOOKUP($A33,Sheet3!C$2:D$10,2,FALSE) -> #N/A | D33: =VLOOKUP($A33,Sheet3!G$2:H$6,2,FALSE) -> #N/A | E33: =VLOOKUP($A33,Sheet3!I$2:J$5,2,FALSE) -> #N/A | F33: =VLOOKUP($A33,Sheet3!E$2:F$6,2,FALSE) -> #N/A | H33: =VLOOKUP($A33,Sheet3!M$2:N$17,2,FALSE) -> #N/A
A34: 黄大豆一号 | C34: =VLOOKUP($A34,Sheet3!C$2:D$10,2,FALSE) -> #N/A | D34: =VLOOKUP($A34,Sheet3!G$2:H$6,2,FALSE) -> #N/A | E34: =VLOOKUP($A34,Sheet3!I$2:J$5,2,FALSE) -> #N/A | F34: =VLOOKUP($A34,Sheet3!E$2:F$6,2,FALSE) -> #N/A | H34: =VLOOKUP($A34,Sheet3!M$2:N$17,2,FALSE) -> #N/A
A35: PVC | C35: =VLOOKUP($A35,Sheet3!C$2:D$10,2,FALSE) -> #N/A | D35: =VLOOKUP($A35,Sheet3!G$2:H$6,2,FALSE) -> #N/A | E35: =VLOOKUP($A35,Sheet3!I$2:J$5,2,FALSE) -> #N/A | F35: =VLOOKUP($A35,Sheet3!E$2:F$6,2,FALSE) -> #N/A
A36: 玉米淀粉 | C36: =VLOOKUP($A36,Sheet3!C$2:D$10,2,FALSE) -> #N/A | D36: =VLOOKUP($A36,Sheet3!G$2:H$6,2,FALSE) -> #N/A | E36: =VLOOKUP($A36,Sheet3!I$2:J$5,2,FALSE) -> #N/A | F36: =VLOOKUP($A36,Sheet3!E$2:F$6,2,FALSE) -> #N/A
A37: 铅 | C37: =VLOOKUP($A37,Sheet3!C$2:D$10,2,FALSE) -> #N/A | D37: =VLOOKUP($A37,Sheet3!G$2:H$6,2,FALSE) -> #N/A | E37: =VLOOKUP($A37,Sheet3!I$2:J$5,2,FALSE) -> #N/A | F37: =VLOOKUP($A37,Sheet3!E$2:F$6,2,FALSE) -> #N/A
A38: 锰硅
A39: 锡
A40: 硅铁

Sheet Sheet3
A1: 南华商品指数 | C1: 工业品 | E1: 农产品 | G1: 金属 | I1: 能化 | K1: 贵金属 | M1: 黑色 | O1: 有色
A2: 原油 | B2: 0.1786 | C2: 原油 | D2: 0.1894 | E2: 苹果 | F2: 0.1639 | G2: 螺纹钢 | H2: 0.25 | I2: 原油 | J2: 0.25 | K2: 黄金 | L2: 0.5935 | M2: 螺纹钢 | N2: 0.3755 | O2: 铜 | P2: 0.3894
A3: 螺纹钢 | B3: 0.1093 | C3: 螺纹钢 | D3: 0.1266 | E3: 豆粕 | F3: 0.1596 | G3: 铁矿石 | H3: 0.2293 | I3: 焦炭 | J3: 0.1223 | K3: 白银 | L3: 0.4065 | M3: 铁矿石 | N3: 0.3009 | O3: 镍 | P3: 0.2342
A4: 铁矿石 | B4: 0.0885 | C4: 铁矿石 | D4: 0.1016 | E4: 白糖 | F4: 0.1125 | G4: 铜 | H4: 0.2095 | I4: 焦煤 | J4: 0.1133 | M4: 焦炭 | N4: 0.2162 | O4: 锌 | P4: 0.1752
A5: 铜 | B5: 0.0809 | C5: 铜 | D5: 0.0928 | E5: 玉米 | F5: 0.0948 | G5: 镍 | H5: 0.1258 | I5: 天然橡胶 | J5: 0.1084 | M5: 焦煤 | N5: 0.1074 | O5: 铝 | P5: 0.1693
A6: 焦炭 | B6: 0.0673 | C6: 焦炭 | D6: 0.0737 | E6: 豆油 | F6: 0.0934 | G6: 锌 | H6: 0.0941 | I6: PTA | J6: 0.0693 | O6: 铅 | P6: 0.0319
A7: 镍 | B7: 0.05 | C7: 镍 | D7: 0.061 | E7: 棕榈油 | F7: 0.0911 | G7: 铝 | H7: 0.0913 | I7: 石油沥青 | J7: 0.0555
A8: 黄金 | B8: 0.0451 | C8: 天然橡胶 | D8: 0.0541 | E8: 一号棉 | F8: 0.0814 | I8: 甲醇 | J8: 0.0521
A9: 天然橡胶 | B9: 0.0442 | C9: 锌 | D9: 0.0443 | E9: 黄大豆一号 | F9: 0.0812 | I9: 聚丙烯 | J9: 0.0479
A10: 苹果 | B10: 0.0422 | C10: PTA | D10: 0.0377 | E10: 鸡蛋 | F10: 0.0538 | I10: 乙二醇 | J10: 0.0462
A11: 豆粕 | B11: 0.0401 | C11: 焦煤 | D11: 0.0372 | E11: 菜籽油 | F11: 0.0483 | I11: 燃料油 | J11: 0.043
A12: 锌 | B12: 0.0371 | C12: 铝 | D12: 0.0357 | E12: 玉米淀粉 | F12: 0.02 | I12: 聚乙烯 | J12: 0.0406
A13: PTA | B13: 0.0325 | C13: 甲醇 | D13: 0.028 | I13: 动力煤 | J13: 0.0283
A14: 白糖 | B14: 0.0279 | C14: 聚乙烯 | D14: 0.028 | I14: 纸浆 | J14: 0.0231
A15: 白银 | B15: 0.026 | C15: 聚丙烯 | D15: 0.0258
A16: 甲醇 | B16: 0.024 | C16: 燃料油 | D16: 0.0226
A17: 豆油 | B17: 0.0234 | C17: 乙二醇 | D17: 0.0215
A18: 棕榈油 | B18: 0.0223 | C18: 石油沥青 | D18: 0.02
A19: 一号棉 | B19: 0.0206
A20: 燃料油 | B20: 0.02
A21: 乙二醇 | B21: 0.02
B22: =SUM(B2:B21) -> 1 | D22: =SUM(D2:D21) -> 1 | F22: =SUM(F2:F21) -> 1 | H22: =SUM(H2:H21) -> 1 | J22: =SUM(J2:J21) -> 1 | L22: =SUM(L2:L21) -> 1 | N22: =SUM(N2:N21) -> 1 | P22: =SUM(P2:P21) -> 1

Sheet Sheet4
A1: 根据南华商品指数编制细则的规定，南华期货有限公司将于2019年6月1日调整南华商品指数权重，具体调整如下：
A2: 品种名称 | B2: 南华商品指数 | C2: 南华工业品指数 | D2: 南华金属指数 | E2: 南华能化指数 | F2: 南华农产品指数 | G2: 南华贵金属指数 | H2: 南华黑色指数 | I2: 南华有色金属指数
A3: 螺纹钢 | B3: 0.1182 | C3: 0.1378 | D3: 0.25 | H3: 0.3572
A4: 铜 | B4: 0.1002 | C4: 0.1165 | D4: 0.2158 | I4: 0.4392
A5: 铁矿石 | B5: 0.0904 | C5: 0.1023 | D5: 0.1887 | H5: 0.2561
A6: 原油 | B6: 0.0895 | C6: 0.1107 | E6: 0.2082
A7: 焦炭 | B7: 0.075 | C7: 0.0809 | E7: 0.1328 | H7: 0.1909
A8: 苹果 | B8: 0.067 | F8: 0.2073
A9: 天然橡胶 | B9: 0.0524 | C9: 0.0668 | E9: 0.1289
A10: 豆粕 | B10: 0.0443 | F10: 0.1425
A11: 黄金 | B11: 0.044 | G11: 0.5935
A12: 镍 | B12: 0.0431 | C12: 0.054 | D12: 0.101 | I12: 0.1981
A13: 锌 | B13: 0.0372 | C13: 0.0453 | D13: 0.0845 | I13: 0.1679
A14: PTA | B14: 0.0322 | C14: 0.0371 | E14: 0.0653
A15: 聚乙烯 | B15: 0.031 | C15: 0.0343 | E15: 0.058
A16: 白银 | B16: 0.0306 | G16: 0.4065
A17: 白糖 | B17: 0.0292 | F17: 0.0972
A18: 聚丙烯 | B18: 0.0262 | C18: 0.0293 | E18: 0.0502
A19: 豆油 | B19: 0.025 | F19: 0.0812
A20: 甲醇 | B20: 0.023 | C20: 0.0268 | E20: 0.0476
A21: 棕榈油 | B21: 0.0215 | F21: 0.0731
A22: 菜籽粕 | B22: 0.02 | F22: 0.0677
A23: 焦煤 | C23: 0.0468 | E23: 0.0699 | H23: 0.0991
A24: 热轧卷板 | C24: 0.0468 | D24: 0.0845 | H24: 0.0967
A25: 铝 | C25: 0.0416 | D25: 0.0755 | I25: 0.1647
A26: 燃料油 | C26: 0.023 | E26: 0.0416
A27: 动力煤 | E27: 0.1482
A28: 石油沥青 | E28: 0.0293
A29: 玻璃 | E29: 0.02
A30: 铅 | I30: 0.0301
A31: 黄大豆一号 | F31: 0.0843
A32: 玉米 | F32: 0.084
A33: 一号棉 | F33: 0.0686
A34: 菜籽油 | F34: 0.0384
A35: 鸡蛋 | F35: 0.034
A36: 玉米淀粉 | F36: 0.0217
